<?xml version="1.0" ?>
<robot name="centres">

  <material name="white">
    <color rgba="1 1 1 1"/>
  </material>

  <material name="grey">
    <color rgba="0.5 0.5 0.5 1.0"/>
  </material>
            
  <material name="blue">
    <color rgba="0 0 .8 1"/>
  </material>

  <link name="noyau">
    <visual>
      <origin rpy="0 0 0" xyz="0 0 0"/>
      <geometry>
		<mesh filename="noyau.stl" scale="0.001 0.001 0.001"/>
      </geometry>
      <material name="grey"/>
    </visual>
    <collision>
      <origin rpy="0 0 0" xyz="0 0 0"/>
      <geometry>
	    <mesh filename="noyau.stl" scale="0.001 0.001 0.001"/>
      </geometry>
    </collision>
  </link>
      
  <link name="centre01">
    <visual>
      <origin rpy="0 0 0" xyz="0 0 0"/>
      <geometry>
		<mesh filename="centre01.stl" scale="0.001 0.001 0.001"/>
      </geometry>
      <material name="white"/>
    </visual>
    <collision>
      <origin rpy="0 0 0" xyz="0 0 0"/>
      <geometry>
	    <mesh filename="centre01.stl" scale="0.001 0.001 0.001"/>
      </geometry>
    </collision>
  </link>

  <link name="centre02">
    <visual>
      <origin rpy="0 0 0" xyz="0 0 0"/>
      <geometry>
		<mesh filename="centre02.stl" scale="0.001 0.001 0.001"/>
      </geometry>
      <material name="white"/>
    </visual>
    <collision>
      <origin rpy="0 0 0" xyz="0 0 0"/>
      <geometry>
	    <mesh filename="centre02.stl" scale="0.001 0.001 0.001"/>
      </geometry>
    </collision>
  </link>

  <link name="centre03">
    <visual>
      <origin rpy="0 0 0" xyz="0 0 0"/>
      <geometry>
		<mesh filename="centre03.stl" scale="0.001 0.001 0.001"/>
      </geometry>
      <material name="white"/>
    </visual>
    <collision>
      <origin rpy="0 0 0" xyz="0 0 0"/>
      <geometry>
	    <mesh filename="centre03.stl" scale="0.001 0.001 0.001"/>
      </geometry>
    </collision>
  </link>

  <link name="centre04">
    <visual>
      <origin rpy="0 0 0" xyz="0 0 0"/>
      <geometry>
		<mesh filename="centre04.stl" scale="0.001 0.001 0.001"/>
      </geometry>
      <material name="white"/>
    </visual>
    <collision>
      <origin rpy="0 0 0" xyz="0 0 0"/>
      <geometry>
	    <mesh filename="centre04.stl" scale="0.001 0.001 0.001"/>
      </geometry>
    </collision>
  </link>

  <link name="centre05">
    <visual>
      <origin rpy="0 0 0" xyz="0 0 0"/>
      <geometry>
		<mesh filename="centre05.stl" scale="0.001 0.001 0.001"/>
      </geometry>
      <material name="white"/>
    </visual>
    <collision>
      <origin rpy="0 0 0" xyz="0 0 0"/>
      <geometry>
	    <mesh filename="centre05.stl" scale="0.001 0.001 0.001"/>
      </geometry>
    </collision>
  </link>
  
  <link name="centre06">
    <visual>
      <origin rpy="0 0 0" xyz="0 0 0"/>
      <geometry>
		<mesh filename="centre06.stl" scale="0.001 0.001 0.001"/>
      </geometry>
      <material name="white"/>
    </visual>
    <collision>
      <origin rpy="0 0 0" xyz="0 0 0"/>
      <geometry>
	    <mesh filename="centre06.stl" scale="0.001 0.001 0.001"/>
      </geometry>
    </collision>
  </link>    
  
  <joint name="centre01_joint" type="continuous">
    <axis xyz="0 0 -1"/>
    <origin xyz="0 0 0"/>
    <parent link="noyau"/>
    <child link="centre01"/>
    <limit effort="100" velocity="100"/>
    <joint_properties damping="0.0" friction="0.0"/>
  </joint>

  <joint name="centre02_joint" type="continuous">
    <axis xyz="0 0 1"/>
    <origin xyz="0 0 0"/>
    <parent link="noyau"/>
    <child link="centre02"/>
    <limit effort="100" velocity="100"/>
    <joint_properties damping="0.0" friction="0.0"/>
  </joint>
  
  <joint name="centre03_joint" type="continuous">
    <axis xyz="0 1 0"/>
    <origin xyz="0 0 0"/>
    <parent link="noyau"/>
    <child link="centre03"/>
    <limit effort="100" velocity="100"/>
    <joint_properties damping="0.0" friction="0.0"/>
  </joint>
  
  <joint name="centre04_joint" type="continuous">
    <axis xyz="0 -1 0"/>
    <origin xyz="0 0 0"/>
    <parent link="noyau"/>
    <child link="centre04"/>
    <limit effort="100" velocity="100"/>
    <joint_properties damping="0.0" friction="0.0"/>
  </joint>
  
  <joint name="centre05_joint" type="continuous">
    <axis xyz="1 0 0"/>
    <origin xyz="0 0 0"/>
    <parent link="noyau"/>
    <child link="centre05"/>
    <limit effort="100" velocity="100"/>
    <joint_properties damping="0.0" friction="0.0"/>
  </joint>
  
  <joint name="centre06_joint" type="continuous">
    <axis xyz="-1 0 0"/>
    <origin xyz="0 0 0"/>
    <parent link="noyau"/>
    <child link="centre06"/>
    <limit effort="100" velocity="100"/>
    <joint_properties damping="0.0" friction="0.0"/>
  </joint>
   
</robot>
