<?xml version="1.0" ?>
<robot name="rubiks">

  <material name="white">
    <color rgba="1 1 1 1"/>
  </material>

  <material name="grey">
    <color rgba="0.5 0.5 0.5 1.0"/>
  </material>
            
  <material name="blue">
    <color rgba="0 0 .8 1"/>
  </material>
      
  <link name="world"/>

  <link name="rubiks">
    <visual>
      <origin rpy="0 0 0" xyz="0 0 0"/>
      <geometry>
		<mesh filename="noyau.stl" scale="0.001 0.001 0.001"/>
      </geometry>
      <material name="grey"/>
    </visual>
    <collision>
      <origin rpy="0 0 0" xyz="0 0 0"/>
      <geometry>
	    <mesh filename="noyau.stl" scale="0.001 0.001 0.001"/>
      </geometry>
    </collision>
  </link>

  <joint name="world_to_rubiks" type="floating">
    <origin xyz="0 0.078575 0" rpy="-0.785398163 0 0"/>
    <parent link="world"/>
    <child link="rubiks"/>
    <limit effort="100" velocity="100"/>
    <joint_properties damping="0.0" friction="0.0"/>
  </joint>
      
  <link name="centre01">
    <visual>
      <origin rpy="0 0 0" xyz="0 0 0"/>
      <geometry>
		<mesh filename="centre01.stl" scale="0.001 0.001 0.001"/>
      </geometry>
      <material name="white"/>
    </visual>
    <collision>
      <origin rpy="0 0 0" xyz="0 0 0"/>
      <geometry>
	    <mesh filename="centre01.stl" scale="0.001 0.001 0.001"/>
      </geometry>
    </collision>
  </link>

  <link name="centre02">
    <visual>
      <origin rpy="0 0 0" xyz="0 0 0"/>
      <geometry>
		<mesh filename="centre02.stl" scale="0.001 0.001 0.001"/>
      </geometry>
      <material name="white"/>
    </visual>
    <collision>
      <origin rpy="0 0 0" xyz="0 0 0"/>
      <geometry>
	    <mesh filename="centre02.stl" scale="0.001 0.001 0.001"/>
      </geometry>
    </collision>
  </link>

  <link name="centre03">
    <visual>
      <origin rpy="0 0 0" xyz="0 0 0"/>
      <geometry>
		<mesh filename="centre03.stl" scale="0.001 0.001 0.001"/>
      </geometry>
      <material name="white"/>
    </visual>
    <collision>
      <origin rpy="0 0 0" xyz="0 0 0"/>
      <geometry>
	    <mesh filename="centre03.stl" scale="0.001 0.001 0.001"/>
      </geometry>
    </collision>
  </link>

  <link name="centre04">
    <visual>
      <origin rpy="0 0 0" xyz="0 0 0"/>
      <geometry>
		<mesh filename="centre04.stl" scale="0.001 0.001 0.001"/>
      </geometry>
      <material name="white"/>
    </visual>
    <collision>
      <origin rpy="0 0 0" xyz="0 0 0"/>
      <geometry>
	    <mesh filename="centre04.stl" scale="0.001 0.001 0.001"/>
      </geometry>
    </collision>
  </link>

  <link name="centre05">
    <visual>
      <origin rpy="0 0 0" xyz="0 0 0"/>
      <geometry>
		<mesh filename="centre05.stl" scale="0.001 0.001 0.001"/>
      </geometry>
      <material name="white"/>
    </visual>
    <collision>
      <origin rpy="0 0 0" xyz="0 0 0"/>
      <geometry>
	    <mesh filename="centre05.stl" scale="0.001 0.001 0.001"/>
      </geometry>
    </collision>
  </link>
  
  <link name="centre06">
    <visual>
      <origin rpy="0 0 0" xyz="0 0 0"/>
      <geometry>
		<mesh filename="centre06.stl" scale="0.001 0.001 0.001"/>
      </geometry>
      <material name="white"/>
    </visual>
    <collision>
      <origin rpy="0 0 0" xyz="0 0 0"/>
      <geometry>
	    <mesh filename="centre06.stl" scale="0.001 0.001 0.001"/>
      </geometry>
    </collision>
  </link>    
  
  <joint name="centre01_joint" type="continuous">
    <axis xyz="0 0 -1"/>
    <origin xyz="0 0 0"/>
    <parent link="rubiks"/>
    <child link="centre01"/>
    <limit effort="100" velocity="100"/>
    <joint_properties damping="0.0" friction="0.0"/>
  </joint>

  <joint name="centre02_joint" type="continuous">
    <axis xyz="0 0 1"/>
    <origin xyz="0 0 0"/>
    <parent link="rubiks"/>
    <child link="centre02"/>
    <limit effort="100" velocity="100"/>
    <joint_properties damping="0.0" friction="0.0"/>
  </joint>
  
  <joint name="centre03_joint" type="continuous">
    <axis xyz="0 1 0"/>
    <origin xyz="0 0 0"/>
    <parent link="rubiks"/>
    <child link="centre03"/>
    <limit effort="100" velocity="100"/>
    <joint_properties damping="0.0" friction="0.0"/>
  </joint>
  
  <joint name="centre04_joint" type="continuous">
    <axis xyz="0 -1 0"/>
    <origin xyz="0 0 0"/>
    <parent link="rubiks"/>
    <child link="centre04"/>
    <limit effort="100" velocity="100"/>
    <joint_properties damping="0.0" friction="0.0"/>
  </joint>
  
  <joint name="centre05_joint" type="continuous">
    <axis xyz="1 0 0"/>
    <origin xyz="0 0 0"/>
    <parent link="rubiks"/>
    <child link="centre05"/>
    <limit effort="100" velocity="100"/>
    <joint_properties damping="0.0" friction="0.0"/>
  </joint>
  
  <joint name="centre06_joint" type="continuous">
    <axis xyz="-1 0 0"/>
    <origin xyz="0 0 0"/>
    <parent link="rubiks"/>
    <child link="centre06"/>
    <limit effort="100" velocity="100"/>
    <joint_properties damping="0.0" friction="0.0"/>
  </joint>
  
  <link name="bord01">
    <visual>
      <origin rpy="0 0 0" xyz="0 0 0"/>
      <geometry>
		<mesh filename="bord01.stl" scale="0.001 0.001 0.001"/>
      </geometry>
      <material name="blue">
        <color rgba="0 0 .8 1"/>
      </material>
    </visual>
    <collision>
      <origin rpy="0 0 0" xyz="0 0 0"/>
      <geometry>
	    <mesh filename="bord01.stl" scale="0.001 0.001 0.001"/>
      </geometry>
    </collision>
  </link>
  
  <joint name="bord01_joint" type="floating">
    <origin xyz="0 0 0"/>
    <parent link="rubiks"/>
    <child link="bord01"/>
    <limit effort="100" velocity="100"/>
    <joint_properties damping="0.0" friction="0.0"/>
  </joint>
  
  <link name="bord02">
    <visual>
      <origin rpy="0 0 0" xyz="0 0 0"/>
      <geometry>
		<mesh filename="bord02.stl" scale="0.001 0.001 0.001"/>
      </geometry>
      <material name="blue">
        <color rgba="0 0 .8 1"/>
      </material>
    </visual>
    <collision>
      <origin rpy="0 0 0" xyz="0 0 0"/>
      <geometry>
	    <mesh filename="bord02.stl" scale="0.001 0.001 0.001"/>
      </geometry>
    </collision>
  </link>
  
  <joint name="bord02_joint" type="floating">
    <origin xyz="0 0 0"/>
    <parent link="rubiks"/>
    <child link="bord02"/>
    <limit effort="100" velocity="100"/>
    <joint_properties damping="0.0" friction="0.0"/>
  </joint>
  
  <link name="bord03">
    <visual>
      <origin rpy="0 0 0" xyz="0 0 0"/>
      <geometry>
		<mesh filename="bord03.stl" scale="0.001 0.001 0.001"/>
      </geometry>
      <material name="blue">
        <color rgba="0 0 .8 1"/>
      </material>
    </visual>
    <collision>
      <origin rpy="0 0 0" xyz="0 0 0"/>
      <geometry>
	    <mesh filename="bord03.stl" scale="0.001 0.001 0.001"/>
      </geometry>
    </collision>
  </link>
  
  <joint name="bord03_joint" type="floating">
    <origin xyz="0 0 0"/>
    <parent link="rubiks"/>
    <child link="bord03"/>
    <limit effort="100" velocity="100"/>
    <joint_properties damping="0.0" friction="0.0"/>
  </joint>
  
  <link name="bord04">
    <visual>
      <origin rpy="0 0 0" xyz="0 0 0"/>
      <geometry>
		<mesh filename="bord04.stl" scale="0.001 0.001 0.001"/>
      </geometry>
      <material name="blue">
        <color rgba="0 0 .8 1"/>
      </material>
    </visual>
    <collision>
      <origin rpy="0 0 0" xyz="0 0 0"/>
      <geometry>
	    <mesh filename="bord04.stl" scale="0.001 0.001 0.001"/>
      </geometry>
    </collision>
  </link>
  
  <joint name="bord04_joint" type="floating">
    <origin xyz="0 0 0"/>
    <parent link="rubiks"/>
    <child link="bord04"/>
    <limit effort="100" velocity="100"/>
    <joint_properties damping="0.0" friction="0.0"/>
  </joint>
  
  <link name="bord05">
    <visual>
      <origin rpy="0 0 0" xyz="0 0 0"/>
      <geometry>
		<mesh filename="bord05.stl" scale="0.001 0.001 0.001"/>
      </geometry>
      <material name="blue">
        <color rgba="0 0 .8 1"/>
      </material>
    </visual>
    <collision>
      <origin rpy="0 0 0" xyz="0 0 0"/>
      <geometry>
	    <mesh filename="bord05.stl" scale="0.001 0.001 0.001"/>
      </geometry>
    </collision>
  </link>
  
  <joint name="bord05_joint" type="floating">
    <origin xyz="0 0 0"/>
    <parent link="rubiks"/>
    <child link="bord05"/>
    <limit effort="100" velocity="100"/>
    <joint_properties damping="0.0" friction="0.0"/>
  </joint>
  
  <link name="bord06">
    <visual>
      <origin rpy="0 0 0" xyz="0 0 0"/>
      <geometry>
		<mesh filename="bord06.stl" scale="0.001 0.001 0.001"/>
      </geometry>
      <material name="blue">
        <color rgba="0 0 .8 1"/>
      </material>
    </visual>
    <collision>
      <origin rpy="0 0 0" xyz="0 0 0"/>
      <geometry>
	    <mesh filename="bord06.stl" scale="0.001 0.001 0.001"/>
      </geometry>
    </collision>
  </link>
  
  <joint name="bord06_joint" type="floating">
    <origin xyz="0 0 0"/>
    <parent link="rubiks"/>
    <child link="bord06"/>
    <limit effort="100" velocity="100"/>
    <joint_properties damping="0.0" friction="0.0"/>
  </joint>
  
  <link name="bord07">
    <visual>
      <origin rpy="0 0 0" xyz="0 0 0"/>
      <geometry>
		<mesh filename="bord07.stl" scale="0.001 0.001 0.001"/>
      </geometry>
      <material name="blue">
        <color rgba="0 0 .8 1"/>
      </material>
    </visual>
    <collision>
      <origin rpy="0 0 0" xyz="0 0 0"/>
      <geometry>
	    <mesh filename="bord07.stl" scale="0.001 0.001 0.001"/>
      </geometry>
    </collision>
  </link>
  
  <joint name="bord07_joint" type="floating">
    <origin xyz="0 0 0"/>
    <parent link="rubiks"/>
    <child link="bord07"/>
    <limit effort="100" velocity="100"/>
    <joint_properties damping="0.0" friction="0.0"/>
  </joint>
  
  <link name="bord08">
    <visual>
      <origin rpy="0 0 0" xyz="0 0 0"/>
      <geometry>
		<mesh filename="bord08.stl" scale="0.001 0.001 0.001"/>
      </geometry>
      <material name="blue">
        <color rgba="0 0 .8 1"/>
      </material>
    </visual>
    <collision>
      <origin rpy="0 0 0" xyz="0 0 0"/>
      <geometry>
	    <mesh filename="bord08.stl" scale="0.001 0.001 0.001"/>
      </geometry>
    </collision>
  </link>
  
  <joint name="bord08_joint" type="floating">
    <origin xyz="0 0 0"/>
    <parent link="rubiks"/>
    <child link="bord08"/>
    <limit effort="100" velocity="100"/>
    <joint_properties damping="0.0" friction="0.0"/>
  </joint>
  
  <link name="bord09">
    <visual>
      <origin rpy="0 0 0" xyz="0 0 0"/>
      <geometry>
		<mesh filename="bord09.stl" scale="0.001 0.001 0.001"/>
      </geometry>
      <material name="blue">
        <color rgba="0 0 .8 1"/>
      </material>
    </visual>
    <collision>
      <origin rpy="0 0 0" xyz="0 0 0"/>
      <geometry>
	    <mesh filename="bord09.stl" scale="0.001 0.001 0.001"/>
      </geometry>
    </collision>
  </link>
  
  <joint name="bord09_joint" type="floating">
    <origin xyz="0 0 0"/>
    <parent link="rubiks"/>
    <child link="bord09"/>
    <limit effort="100" velocity="100"/>
    <joint_properties damping="0.0" friction="0.0"/>
  </joint>
  
  <link name="bord10">
    <visual>
      <origin rpy="0 0 0" xyz="0 0 0"/>
      <geometry>
		<mesh filename="bord10.stl" scale="0.001 0.001 0.001"/>
      </geometry>
      <material name="blue">
        <color rgba="0 0 .8 1"/>
      </material>
    </visual>
    <collision>
      <origin rpy="0 0 0" xyz="0 0 0"/>
      <geometry>
	    <mesh filename="bord10.stl" scale="0.001 0.001 0.001"/>
      </geometry>
    </collision>
  </link>
  
  <joint name="bord10_joint" type="floating">
    <origin xyz="0 0 0"/>
    <parent link="rubiks"/>
    <child link="bord10"/>
    <limit effort="100" velocity="100"/>
    <joint_properties damping="0.0" friction="0.0"/>
  </joint>
  
  <link name="bord11">
    <visual>
      <origin rpy="0 0 0" xyz="0 0 0"/>
      <geometry>
		<mesh filename="bord11.stl" scale="0.001 0.001 0.001"/>
      </geometry>
      <material name="blue">
        <color rgba="0 0 .8 1"/>
      </material>
    </visual>
    <collision>
      <origin rpy="0 0 0" xyz="0 0 0"/>
      <geometry>
	    <mesh filename="bord11.stl" scale="0.001 0.001 0.001"/>
      </geometry>
    </collision>
  </link>
  
  <joint name="bord11_joint" type="floating">
    <origin xyz="0 0 0"/>
    <parent link="rubiks"/>
    <child link="bord11"/>
    <limit effort="100" velocity="100"/>
    <joint_properties damping="0.0" friction="0.0"/>
  </joint>
  
  <link name="bord12">
    <visual>
      <origin rpy="0 0 0" xyz="0 0 0"/>
      <geometry>
		<mesh filename="bord12.stl" scale="0.001 0.001 0.001"/>
      </geometry>
      <material name="blue">
        <color rgba="0 0 .8 1"/>
      </material>
    </visual>
    <collision>
      <origin rpy="0 0 0" xyz="0 0 0"/>
      <geometry>
	    <mesh filename="bord12.stl" scale="0.001 0.001 0.001"/>
      </geometry>
    </collision>
  </link>
  
  <joint name="bord12_joint" type="floating">
    <origin xyz="0 0 0"/>
    <parent link="rubiks"/>
    <child link="bord12"/>
    <limit effort="100" velocity="100"/>
    <joint_properties damping="0.0" friction="0.0"/>
  </joint>
  
  <link name="coin01">
    <visual>
      <origin rpy="0 0 0" xyz="0 0 0"/>
      <geometry>
		<mesh filename="coin01.stl" scale="0.001 0.001 0.001"/>
      </geometry>
      <material name="blue">
        <color rgba="0 0 .8 1"/>
      </material>
    </visual>
    <collision>
      <origin rpy="0 0 0" xyz="0 0 0"/>
      <geometry>
	    <mesh filename="coin01.stl" scale="0.001 0.001 0.001"/>
      </geometry>
    </collision>
  </link>
  
  <joint name="coin01_joint" type="floating">
    <origin xyz="0 0 0"/>
    <parent link="rubiks"/>
    <child link="coin01"/>
    <limit effort="100" velocity="100"/>
    <joint_properties damping="0.0" friction="0.0"/>
  </joint>  
  
  <link name="coin02">
    <visual>
      <origin rpy="0 0 0" xyz="0 0 0"/>
      <geometry>
		<mesh filename="coin02.stl" scale="0.001 0.001 0.001"/>
      </geometry>
      <material name="blue">
        <color rgba="0 0 .8 1"/>
      </material>
    </visual>
    <collision>
      <origin rpy="0 0 0" xyz="0 0 0"/>
      <geometry>
	    <mesh filename="coin02.stl" scale="0.001 0.001 0.001"/>
      </geometry>
    </collision>
  </link>
  
  <joint name="coin02_joint" type="floating">
    <origin xyz="0 0 0"/>
    <parent link="rubiks"/>
    <child link="coin02"/>
    <limit effort="100" velocity="100"/>
    <joint_properties damping="0.0" friction="0.0"/>
  </joint>  
  
  <link name="coin03">
    <visual>
      <origin rpy="0 0 0" xyz="0 0 0"/>
      <geometry>
		<mesh filename="coin03.stl" scale="0.001 0.001 0.001"/>
      </geometry>
      <material name="blue">
        <color rgba="0 0 .8 1"/>
      </material>
    </visual>
    <collision>
      <origin rpy="0 0 0" xyz="0 0 0"/>
      <geometry>
	    <mesh filename="coin03.stl" scale="0.001 0.001 0.001"/>
      </geometry>
    </collision>
  </link>
  
  <joint name="coin03_joint" type="floating">
    <origin xyz="0 0 0"/>
    <parent link="rubiks"/>
    <child link="coin03"/>
    <limit effort="100" velocity="100"/>
    <joint_properties damping="0.0" friction="0.0"/>
  </joint>  
  
  <link name="coin04">
    <visual>
      <origin rpy="0 0 0" xyz="0 0 0"/>
      <geometry>
		<mesh filename="coin04.stl" scale="0.001 0.001 0.001"/>
      </geometry>
      <material name="blue">
        <color rgba="0 0 .8 1"/>
      </material>
    </visual>
    <collision>
      <origin rpy="0 0 0" xyz="0 0 0"/>
      <geometry>
	    <mesh filename="coin04.stl" scale="0.001 0.001 0.001"/>
      </geometry>
    </collision>
  </link>
  
  <joint name="coin04_joint" type="floating">
    <origin xyz="0 0 0"/>
    <parent link="rubiks"/>
    <child link="coin04"/>
    <limit effort="100" velocity="100"/>
    <joint_properties damping="0.0" friction="0.0"/>
  </joint>  
  
  <link name="coin05">
    <visual>
      <origin rpy="0 0 0" xyz="0 0 0"/>
      <geometry>
		<mesh filename="coin05.stl" scale="0.001 0.001 0.001"/>
      </geometry>
      <material name="blue">
        <color rgba="0 0 .8 1"/>
      </material>
    </visual>
    <collision>
      <origin rpy="0 0 0" xyz="0 0 0"/>
      <geometry>
	    <mesh filename="coin05.stl" scale="0.001 0.001 0.001"/>
      </geometry>
    </collision>
  </link>
  
  <joint name="coin05_joint" type="floating">
    <origin xyz="0 0 0"/>
    <parent link="rubiks"/>
    <child link="coin05"/>
    <limit effort="100" velocity="100"/>
    <joint_properties damping="0.0" friction="0.0"/>
  </joint>  
  
  <link name="coin06">
    <visual>
      <origin rpy="0 0 0" xyz="0 0 0"/>
      <geometry>
		<mesh filename="coin06.stl" scale="0.001 0.001 0.001"/>
      </geometry>
      <material name="blue">
        <color rgba="0 0 .8 1"/>
      </material>
    </visual>
    <collision>
      <origin rpy="0 0 0" xyz="0 0 0"/>
      <geometry>
	    <mesh filename="coin06.stl" scale="0.001 0.001 0.001"/>
      </geometry>
    </collision>
  </link>
  
  <joint name="coin06_joint" type="floating">
    <origin xyz="0 0 0"/>
    <parent link="rubiks"/>
    <child link="coin06"/>
    <limit effort="100" velocity="100"/>
    <joint_properties damping="0.0" friction="0.0"/>
  </joint>  
  
  <link name="coin07">
    <visual>
      <origin rpy="0 0 0" xyz="0 0 0"/>
      <geometry>
		<mesh filename="coin07.stl" scale="0.001 0.001 0.001"/>
      </geometry>
      <material name="blue">
        <color rgba="0 0 .8 1"/>
      </material>
    </visual>
    <collision>
      <origin rpy="0 0 0" xyz="0 0 0"/>
      <geometry>
	    <mesh filename="coin07.stl" scale="0.001 0.001 0.001"/>
      </geometry>
    </collision>
  </link>
  
  <joint name="coin07_joint" type="floating">
    <origin xyz="0 0 0"/>
    <parent link="rubiks"/>
    <child link="coin07"/>
    <limit effort="100" velocity="100"/>
    <joint_properties damping="0.0" friction="0.0"/>
  </joint>  
  
  <link name="coin08">
    <visual>
      <origin rpy="0 0 0" xyz="0 0 0"/>
      <geometry>
		<mesh filename="coin08.stl" scale="0.001 0.001 0.001"/>
      </geometry>
      <material name="blue">
        <color rgba="0 0 .8 1"/>
      </material>
    </visual>
    <collision>
      <origin rpy="0 0 0" xyz="0 0 0"/>
      <geometry>
	    <mesh filename="coin08.stl" scale="0.001 0.001 0.001"/>
      </geometry>
    </collision>
  </link>
  
  <joint name="coin08_joint" type="floating">
    <origin xyz="0 0 0"/>
    <parent link="rubiks"/>
    <child link="coin08"/>
    <limit effort="100" velocity="100"/>
    <joint_properties damping="0.0" friction="0.0"/>
  </joint>  
</robot>
